<?xml version="1.0" ?>
<!-- =================================================================================== -->
<!-- |    This document was autogenerated by xacro from URDF_finger_4_motors2.xacro    | -->
<!-- |    EDITING THIS FILE BY HAND IS NOT RECOMMENDED                                 | -->
<!-- =================================================================================== -->
<robot name="URDF_finger_4_motors">

<mujoco>
        <compiler
        meshdir="/home/lasa/research/projects/crawling_hand/crawling_hand/descriptions/v2/meshes/"
        balanceinertia="true"
        discardvisual="true" />
  </mujoco>

  <link name="base_link">
    <inertial>
      <origin rpy="0 0 0" xyz="3.799405234872211e-14 3.555738008582665e-06 0.004698273696115776"/>
      <mass value="0.004531103214243683"/>
      <inertia ixx="0.0" ixy="0.0" ixz="0.0" iyy="0.0" iyz="0.0" izz="0.0"/>
    </inertial>
    <visual>
      <origin rpy="0 0 0" xyz="0 0 0"/>
      <geometry>
        <mesh filename="base_link.stl" scale="0.001 0.001 0.001"/>
      </geometry>
      <material name="silver"/>
    </visual>
    <collision>
      <origin rpy="0 0 0" xyz="0 0 0"/>
      <geometry>
        <mesh filename="file:///home/lasa/research/projects/crawling_hand/URDF_finger_4_motors_description/meshes/base_link.stl" scale="0.001 0.001 0.001"/>
      </geometry>
    </collision>
  </link>
  <link name="MCP_spread_motor_1">
    <inertial>
      <origin rpy="0 0 0" xyz="0.014504402576549202 0.015961701754002047 -0.0007493794787819469"/>
      <mass value="0.11379089624899982"/>
      <inertia ixx="1.6e-05" ixy="0.0" ixz="-0.0" iyy="8e-06" iyz="0.0" izz="1.5e-05"/>
    </inertial>
    <visual>
      <origin rpy="0 0 0" xyz="0 0 0"/>
      <geometry>
        <mesh filename="file:///home/lasa/research/projects/crawling_hand/URDF_finger_4_motors_description/meshes/MCP_spread_motor_1.stl" scale="0.001 0.001 0.001"/>
      </geometry>
      <material name="silver"/>
    </visual>
    <collision>
      <origin rpy="0 0 0" xyz="0 0 0"/>
      <geometry>
        <mesh filename="file:///home/lasa/research/projects/crawling_hand/URDF_finger_4_motors_description/meshes/MCP_spread_motor_1.stl" scale="0.001 0.001 0.001"/>
      </geometry>
    </collision>
  </link>
  <link name="MCP_motor_1">
    <inertial>
      <origin rpy="0 0 0" xyz="0.01275062052121805 0.007538298245997978 4.402576549209988e-06"/>
      <mass value="0.11379089624899982"/>
      <inertia ixx="1.5e-05" ixy="-0.0" ixz="-0.0" iyy="8e-06" iyz="-0.0" izz="1.6e-05"/>
    </inertial>
    <visual>
      <origin rpy="0 0 0" xyz="0.0135 -0.0235 0.008"/>
      <geometry>
        <mesh filename="file:///home/lasa/research/projects/crawling_hand/URDF_finger_4_motors_description/meshes/MCP_motor_1.stl" scale="0.001 0.001 0.001"/>
      </geometry>
      <material name="silver"/>
    </visual>
    <collision>
      <origin rpy="0 0 0" xyz="0.0135 -0.0235 0.008"/>
      <geometry>
        <mesh filename="file:///home/lasa/research/projects/crawling_hand/URDF_finger_4_motors_description/meshes/MCP_motor_1.stl" scale="0.001 0.001 0.001"/>
      </geometry>
    </collision>
  </link>
  <link name="proximal_1">
    <inertial>
      <origin rpy="0 0 0" xyz="-0.009220356752702732 0.012499163175217737 -0.008000000000001731"/>
      <mass value="0.04954129030393856"/>
      <inertia ixx="6e-06" ixy="-1e-06" ixz="0.0" iyy="9e-06" iyz="0.0" izz="1.2e-05"/>
    </inertial>
    <visual>
      <origin rpy="0 0 0" xyz="-0.0105 -0.046 -0.0"/>
      <geometry>
        <mesh filename="file:///home/lasa/research/projects/crawling_hand/URDF_finger_4_motors_description/meshes/proximal_1.stl" scale="0.001 0.001 0.001"/>
      </geometry>
      <material name="silver"/>
    </visual>
    <collision>
      <origin rpy="0 0 0" xyz="-0.0105 -0.046 -0.0"/>
      <geometry>
        <mesh filename="file:///home/lasa/research/projects/crawling_hand/URDF_finger_4_motors_description/meshes/proximal_1.stl" scale="0.001 0.001 0.001"/>
      </geometry>
    </collision>
  </link>
  <link name="PIP_motor_1">
    <inertial>
      <origin rpy="0 0 0" xyz="0.011750620521217897 0.007538298245998248 4.402576549341827e-06"/>
      <mass value="0.11379089624899982"/>
      <inertia ixx="1.5e-05" ixy="-0.0" ixz="-0.0" iyy="8e-06" iyz="-0.0" izz="1.6e-05"/>
    </inertial>
    <visual>
      <origin rpy="0 0 0" xyz="0.0125 -0.0725 0.008"/>
      <geometry>
        <mesh filename="file:///home/lasa/research/projects/crawling_hand/URDF_finger_4_motors_description/meshes/PIP_motor_1.stl" scale="0.001 0.001 0.001"/>
      </geometry>
      <material name="silver"/>
    </visual>
    <collision>
      <origin rpy="0 0 0" xyz="0.0125 -0.0725 0.008"/>
      <geometry>
        <mesh filename="file:///home/lasa/research/projects/crawling_hand/URDF_finger_4_motors_description/meshes/PIP_motor_1.stl" scale="0.001 0.001 0.001"/>
      </geometry>
    </collision>
  </link>
  <link name="middle_1">
    <inertial>
      <origin rpy="0 0 0" xyz="-0.00922035675270308 0.01249916317521807 -0.008000000000001705"/>
      <mass value="0.04954129030393859"/>
      <inertia ixx="6e-06" ixy="-1e-06" ixz="0.0" iyy="9e-06" iyz="0.0" izz="1.2e-05"/>
    </inertial>
    <visual>
      <origin rpy="0 0 0" xyz="-0.0105 -0.095 -0.0"/>
      <geometry>
        <mesh filename="file:///home/lasa/research/projects/crawling_hand/URDF_finger_4_motors_description/meshes/middle_1.stl" scale="0.001 0.001 0.001"/>
      </geometry>
      <material name="silver"/>
    </visual>
    <collision>
      <origin rpy="0 0 0" xyz="-0.0105 -0.095 -0.0"/>
      <geometry>
        <mesh filename="file:///home/lasa/research/projects/crawling_hand/URDF_finger_4_motors_description/meshes/middle_1.stl" scale="0.001 0.001 0.001"/>
      </geometry>
    </collision>
  </link>
  <link name="DIP_motor_1">
    <inertial>
      <origin rpy="0 0 0" xyz="0.01175062052121759 0.007538298245998387 4.402576549360909e-06"/>
      <mass value="0.11379089624899982"/>
      <inertia ixx="1.5e-05" ixy="-0.0" ixz="-0.0" iyy="8e-06" iyz="-0.0" izz="1.6e-05"/>
    </inertial>
    <visual>
      <origin rpy="0 0 0" xyz="0.0125 -0.1215 0.008"/>
      <geometry>
        <mesh filename="file:///home/lasa/research/projects/crawling_hand/URDF_finger_4_motors_description/meshes/DIP_motor_1.stl" scale="0.001 0.001 0.001"/>
      </geometry>
      <material name="silver"/>
    </visual>
    <collision>
      <origin rpy="0 0 0" xyz="0.0125 -0.1215 0.008"/>
      <geometry>
        <mesh filename="file:///home/lasa/research/projects/crawling_hand/URDF_finger_4_motors_description/meshes/DIP_motor_1.stl" scale="0.001 0.001 0.001"/>
      </geometry>
    </collision>
  </link>
  <link name="distal_1">
    <inertial>
      <origin rpy="0 0 0" xyz="0.008558967783568232 0.1674005201629926 -0.010499974691148698"/>
      <mass value="0.049733622959558965"/>
      <inertia ixx="5e-06" ixy="0.0" ixz="0.0" iyy="9e-06" iyz="0.0" izz="9e-06"/>
    </inertial>
    <visual>
      <origin rpy="0 0 0" xyz="0.009 0.0225 -0.0025"/>
      <geometry>
        <mesh filename="file:///home/lasa/research/projects/crawling_hand/URDF_finger_4_motors_description/meshes/distal_1.stl" scale="0.001 0.001 0.001"/>
      </geometry>
      <material name="silver"/>
    </visual>
    <collision>
      <origin rpy="0 0 0" xyz="0.009 0.0225 -0.0025"/>
      <geometry>
        <mesh filename="file:///home/lasa/research/projects/crawling_hand/URDF_finger_4_motors_description/meshes/distal_1.stl" scale="0.001 0.001 0.001"/>
      </geometry>
    </collision>
  </link>
  <link name="metacarpal_1">
    <inertial>
      <origin rpy="0 0 0" xyz="0.0005018454812299407 0.02234267107533321 -0.0005002364022809631"/>
      <mass value="0.10432007000540634"/>
      <inertia ixx="2.6e-05" ixy="-1e-06" ixz="0.0" iyy="2.4e-05" iyz="-0.0" izz="4e-05"/>
    </inertial>
    <visual>
      <origin rpy="0 0 0" xyz="-0.0 0.0245 0.0075"/>
      <geometry>
        <mesh filename="file:///home/lasa/research/projects/crawling_hand/URDF_finger_4_motors_description/meshes/metacarpal_1.stl" scale="0.001 0.001 0.001"/>
      </geometry>
      <material name="silver"/>
    </visual>
    <collision>
      <origin rpy="0 0 0" xyz="-0.0 0.0245 0.0075"/>
      <geometry>
        <mesh filename="file:///home/lasa/research/projects/crawling_hand/URDF_finger_4_motors_description/meshes/metacarpal_1.stl" scale="0.001 0.001 0.001"/>
      </geometry>
    </collision>
  </link>
  <joint name="MCP_spread" type="continuous">
    <!-- <origin rpy="0 0 0" xyz="-0.0145 -0.0235 -0.007"/> -->
    <parent link="base_link"/>
    <child link="MCP_spread_motor_1"/>
    <axis xyz="-0.0 -0.0 1.0"/>
  </joint>
  <joint name="MCP" type="continuous">
    <origin rpy="0 0 0" xyz="-0.0135 0.048 -0.0005"/>
    <parent link="metacarpal_1"/>
    <child link="MCP_motor_1"/>
    <axis xyz="1.0 0.0 0.0"/>
  </joint>
  <joint name="MCP_link" type="fixed">
    <origin rpy="0 0 0" xyz="0.024 0.0225 0.008"/>
    <parent link="MCP_motor_1"/>
    <child link="proximal_1"/>
  </joint>
  <joint name="PIP" type="continuous">
    <origin rpy="0 0 0" xyz="-0.023 0.0265 -0.008"/>
    <parent link="proximal_1"/>
    <child link="PIP_motor_1"/>
    <axis xyz="1.0 0.0 -0.0"/>
  </joint>
  <joint name="PIP_link" type="fixed">
    <origin rpy="0 0 0" xyz="0.023 0.0225 0.008"/>
    <parent link="PIP_motor_1"/>
    <child link="middle_1"/>
  </joint>
  <joint name="DIP" type="continuous">
    <origin rpy="0 0 0" xyz="-0.023 0.0265 -0.008"/>
    <parent link="middle_1"/>
    <child link="DIP_motor_1"/>
    <axis xyz="1.0 0.0 -0.0"/>
  </joint>
  <joint name="DIP_link" type="fixed">
    <origin rpy="0 0 0" xyz="0.0035 -0.144 0.0105"/>
    <parent link="DIP_motor_1"/>
    <child link="distal_1"/>
  </joint>
  <joint name="MCP_spread_link" type="fixed">
    <!-- <origin rpy="0 0 0" xyz="0.0145 -0.001 -0.0005"/> -->
    <origin rpy="0 0 0" xyz="0 -0.0155 -0.0075"/>
    <parent link="MCP_spread_motor_1"/>
    <child link="metacarpal_1"/>
  </joint>
</robot>
