


<mujoco model="iiwa7">
    <compiler angle="radian" inertiafromgeom="true" meshdir="/home/xiao/research/lasa/mujoco_new/crawling_robot/descriptions/single_finger/shortest/meshes/"/>
    <size njmax="500" nconmax="100" />

    <option>
        <flag gravity="enable" />
    </option>

    <default>
        <joint limited='true' damping='1' armature='0'/>
        <geom contype='1' conaffinity='1' condim='3' rgba='0.8 0.6 .4 1'
        	margin="0.001" solref=".02 1" solimp=".8 .8 .01" material="geom"/>
    </default>

 <default>
    <joint damping="0.01" frictionloss="0"/>
    <default class="visual">
      <geom contype="0" conaffinity="0"/>
    </default>
    <default class="collision">
      <geom contype="1" conaffinity="1" friction="1 0.5 0.1" />
    </default>
      <default class="obj">
      <geom condim="6" friction="1 0.5 0.1"  />
    </default>

      <default class="fingers">
      <geom friction="1 0.5 0.2"  />
    </default>
      <default class="visual1">
      <geom contype="1" conaffinity="1"/>
    </default>
        <default class="visual2">
     <geom contype="1" conaffinity="1"/>
    </default>
        <default class="visual3">
     <geom contype="1" conaffinity="1"/>
    </default>
        <default class="visual4">
     <geom contype="1" conaffinity="1"/>
    </default>
        <default class="visual5">
      <geom contype="1" conaffinity="1"/>
    </default>

    <site rgba="1 0 0 .5"/>
  </default>

        <asset>
            <mesh name="base_link" file="base_link.stl" scale="0.001 0.001 0.001" />
            <mesh name="MCP_spread_motor_1" file="MCP_spread_motor_1.stl" scale="0.001 0.001 0.001" />
            <mesh name="MCP_motor_1" file="MCP_motor_1.stl" scale="0.001 0.001 0.001" />
            <mesh name="proximal_1" file="proximal_1.stl" scale="0.001 0.001 0.001" />
            <mesh name="PIP_DIP_motor_1" file="PIP_DIP_motor_1.stl" scale="0.001 0.001 0.001" />
            <mesh name="middle_1" file="middle_1.stl" scale="0.001 0.001 0.001" />
            <mesh name="distal_1" file="distal_1.stl" scale="0.001 0.001 0.001" />
            <mesh name="metacarpal_1" file="metacarpal_1.stl" scale="0.001 0.001 0.001" />
<!--		<texture type="skybox" builtin="gradient" width="128" height="128" rgb1=".4 .6 .8"-->
<!--            rgb2="0 0 0"/>-->
            <texture name="texgeom" type="cube" builtin="flat" mark="cross" width="127" height="1278"
                rgb1="0.8 0.6 0.4" rgb2="0.8 0.6 0.4" markrgb="1 1 1" random="0.01"/>
            <texture name="texplane" type="2d" builtin="checker" rgb1=".2 .3 .4" rgb2=".1 0.15 0.2"
                width="512" height="512"/>

            <material name='MatPlane' reflectance='0.5' texture="texplane" texrepeat="1 1" texuniform="true"/>
            <material name='geom' texture="texgeom" texuniform="true"/>
             <texture builtin="flat" name="allegro_mount_tex" height="32" width="32" rgb1="0.2 0.2 0.2" type="cube"/>
             <texture builtin="flat" name="hand_tex" height="32" width="32" rgb1="0.2 0.2 0.2 " type="cube"/>
             <texture builtin="flat" name="tip_tex" height="32" width="32" rgb1="0.9 0.9 0.9" type="cube"/>

            <material name="allegro_mount_mat" shininess="0.03" specular="0.25"/>
            <material name="hand_mat" shininess="0.03" specular="0.25" />
            <material name="tip_mat" shininess="0.03" specular="0.25" />
        </asset>

    <worldbody>
        <light pos="0 0 10" castshadow="false"/>
         <light directional='false' diffuse='.8 .8 .8' specular='0.3 0.3 0.3' pos='0 0 4.0' dir='0 -.15 -1'/>
<!--        <body name="world_base" euler="0 0 0" pos="0 0 0.0">-->
<!--            <geom name="floor" class="collision" type="plane" size="10 10 1" rgba=".8 .8 .8 1" material="MatPlane"/>-->
<!--        </body>-->


        <body name="finger_1" pos="0 0 0">
    <!--            <geom pos="0 -0.01 0.007" quat="1 0 0 0" type="box" size="0.015 0.02 0.002" rgba="0.1 1 .1 1"/>-->
                <geom type="mesh" rgba="0.7 0.7 0.7 1" mesh="base_link" />
                <body name="MCP_spread_motor_1" pos="0 0 0.0036">
                    <inertial pos="0.000245265 -0.00496883 -0.0114693" quat="0.524663 0.474196 -0.523113 0.475625" mass="0.21816" diaginertia="5.65844e-05 4.36866e-05 3.19042e-05" />
                    <joint name="MCP_spread_1" type="hinge" pos="0 0 0" axis="0 0 -1" range="-2 2" />
                    <geom pos="0 0 -0.0036" type="mesh" rgba="0.7 0.7 0.7 1" mesh="MCP_spread_motor_1" name="MCP_spread_motor_1"/>
                    <geom pos="0 0 -0.0036" type="mesh" rgba="0.7 0.7 0.7 1" mesh="metacarpal_1" name="metacarpal_1"/>
                    <body name="MCP_motor_1" pos="0.0106 0.0235 -0.0116">
                        <inertial pos="-0.0103512 0.0125458 3.30732e-06" quat="0.535591 0.461692 -0.535523 0.461734" mass="0.151474" diaginertia="3.89252e-05 3.18099e-05 1.61153e-05" />
                        <joint name="MCP_1" pos="0 0 0" axis="-1 0 0" range="-2 2" />
                        <geom pos="-0.0106 -0.0235 0.008" type="mesh" rgba="0.7 0.7 0.7 1" mesh="MCP_motor_1" name="MCP_motor_1"/>
                        <geom pos="-0.0106 -0.0235 0.008" type="mesh" rgba="0.7 0.7 0.7 1" mesh="proximal_1" name="proximal_1"/>
                        <body name="PIP_DIP_motor_1" pos="0 0.039 0">
                            <inertial pos="-0.010709 0.0103943 3.56469e-06" quat="0.533676 0.463904 -0.533611 0.463942" mass="0.140537" diaginertia="2.81223e-05 2.20307e-05 1.40916e-05" />
                            <joint name="PIP_1" pos="0 0 0" axis="-1 0 0" range="-2 2" />
                            <geom pos="-0.0106 -0.0625 0.008" type="mesh" rgba="0 0.7 0 1" mesh="PIP_DIP_motor_1" name="PIP_DIP_motor_1" />
                            <geom pos="-0.0106 -0.0625 0.008" type="mesh" rgba="0 0.7 0 1" mesh="middle_1" name="middle_1"/>
                            <body name="distal_1" pos="0.0029 0.0305 0">
                                <inertial pos="-0.0135 0.0167496 0" quat="0.5 0.5 -0.5 0.5" mass="0.112487" diaginertia="1.8e-05 1.7e-05 8e-06" />
                                <joint name="DIP_1" pos="0 0 0" axis="1 0 0"  range="-2 2"/>
                                <geom pos="-0.0135 -0.093 0.008" type="mesh" rgba="0 0.7 0 1" mesh="distal_1" name="distal_1"/>
                                <site name="finger_1_tip" pos="-0.0135 0.026 0" euler="0 0 0" size="0.005  0.005 0.005"/>
                            </body>
                        </body>
                    </body>
                </body>
         </body>



    </worldbody>



      <actuator>
          <motor name="joint_11" ctrllimited="true" ctrlrange="-3 3" joint="MCP_spread_1"/>
          <motor name="joint_12" ctrllimited="true" ctrlrange="-3 3" joint="MCP_1"/>
          <motor name="joint_13" ctrllimited="true" ctrlrange="-3 3" joint="PIP_1"/>
          <motor name="joint_14" ctrllimited="true" ctrlrange="-3 3" joint="DIP_1"/>
    </actuator>


</mujoco>



